Workbook
Name Attempt: [1]Lookup!$D$63:$D$64
Name Complete: [1]Lookup!$C$63:$C$65
Name Direction: Table247[Direction Short]
Name Distance: Lookup!$A$69:$A$103
Name Down: Lookup!$B$63:$B$67
Name Gap: Table1[Gap]
Name Hash: Table24[Hash Short]
Name Motion: Table4[Motion Short]
Name ODK: Table7[ODK Short]
Name PassData: 'Chart Data'!$A$2:$D$11
Name PlayData: Table11[#All]
Name PlayType: Table8[Play Type Long]
Name QTR: Table1[Qtr]
Name Strength: Table2[Strength Short]
Name Zone: Table246[Pass Zone Short]

Sheet Passing Chart
A1: Pass Attempts by Zone
B2: Left | H2: Middle | N2: Right
B3: =IFERROR(TEXT(GETPIVOTDATA("Attempted",Refresh!$A$9,"Direction","L")/GETPIVOTDATA("Attempted",Refresh!$A$9),"##0%"),"0") -> 29% | H3: =IFERROR(TEXT(GETPIVOTDATA("Attempted",Refresh!$A$9,"Direction","M")/GETPIVOTDATA("Attempted",Refresh!$A$9),"##0%"),"0") -> 41% | N3: =IFERROR(TEXT(GETPIVOTDATA("Attempted",Refresh!$A$9,"Direction","R")/GETPIVOTDATA("Attempted",Refresh!$A$9),"##0%"),"0") -> 31%
B4: =TEXT(IFERROR(GETPIVOTDATA("Yard",Refresh!$A$9,"Direction","L"),0),"#,##0")&" yards"&" ("&TEXT(IFERROR(GETPIVOTDATA("Yard",Refresh!$A$9,"Direction","L")/GETPIVOTDATA("Yard",Refresh!$A$9),0),"##0%")&")" -> 134 yards (56%) | H4: =TEXT(IFERROR(GETPIVOTDATA("Yard",Refresh!$A$9,"Direction","M"),0),"#,##0")&" yards"&" ("&TEXT(IFERROR(GETPIVOTDATA("Yard",Refresh!$A$9,"Direction","m")/GETPIVOTDATA("Yard",Refresh!$A$9),0),"##0%")&")" -> -114 yards (-48%) | N4: =TEXT(IFERROR(GETPIVOTDATA("Yard",Refresh!$A$9,"Direction","R"),0),"#,##0")&" yards"&" ("&TEXT(IFERROR(GETPIVOTDATA("Yard",Refresh!$A$9,"Direction","R")/GETPIVOTDATA("Yard",Refresh!$A$9),0),"##0%")&")" -> 218 yards (92%)

Sheet Run Chart
A1: Rushing Attempts by Gap
C2: Left | K2: Right
C3: =TEXT(IFERROR(GETPIVOTDATA("Sum of Attempts",Refresh!$A$25,"Direction","L"),0),"##0%") -> 39% | K3: =TEXT(IFERROR(GETPIVOTDATA("Sum of Attempts",Refresh!$A$25,"Direction","R"),0),"##0%") -> 61%
C4: =TEXT(IFERROR(GETPIVOTDATA("Sum of Yards",Refresh!$A$25,"Direction","L"),0),"#,##0")&" yards"&" ("&TEXT(IFERROR(GETPIVOTDATA("Sum of Yards2",Refresh!$A$25,"Direction","L"),0),"##0%")&")" -> 557 yards (37%) | K4: =TEXT(IFERROR(GETPIVOTDATA("Sum of Yards",Refresh!$A$25,"Direction","r"),0),"#,##0")&" yards"&" ("&TEXT(IFERROR(GETPIVOTDATA("Sum of Yards2",Refresh!$A$25,"Direction","r"),0),"##0%")&")" -> 942 yards (63%)

Sheet Summary
A1: Run / Pass | F1: Down | J1: Down & Distance | N1: Field Postion
B2: Attempts | C2: Yards | D2: Avg | G2: Run | H2: Pass | K2: Run | L2: Pass | O2: Run | P2: Pass
A3: Run | B3: =TEXT(IFERROR(GETPIVOTDATA("Count of Play",Refresh!$A$47,"Play Type","Run"),0),"##0%") -> 72% | C3: =TEXT(GETPIVOTDATA("Yards ",Refresh!$A$47,"Play Type","Run"),"#,##0") -> 1,499 | D3: =TEXT(IFERROR(GETPIVOTDATA("Sum of Yds per Att",Refresh!$A$47,"Play Type","Run"),0),"###0.0") -> 5.5 | F3: 1st | G3: =TEXT(IFERROR(GETPIVOTDATA("% Attempts",Refresh!$A$68,"Down",1,"Play Type","Run"),0),"##0%") -> 78% | H3: =TEXT(IFERROR(GETPIVOTDATA("% Attempts",Refresh!$A$68,"Down",1,"Play Type","Pass"),0),"##0%") -> 22% | J3: 1st & 10+ | K3: =TEXT(IFERROR(GETPIVOTDATA("% Attempts",Refresh!$A$148,"Play Type","Run","D&D","01: 1st & 10+"),0),"##0%") -> 79% | L3: =TEXT(IFERROR(GETPIVOTDATA("% Attempts",Refresh!$A$148,"Play Type","Pass","D&D","01: 1st & 10+"),0),"##0%") -> 21% | N3: 0 - 20 | O3: =TEXT(IFERROR(GETPIVOTDATA("% Attempts",Refresh!$A$125,"Play Type","Run","Yard Line Zone","0-20"),0),"##0%") -> 67% | P3: =TEXT(IFERROR(GETPIVOTDATA("% Attempts",Refresh!$A$125,"Play Type","Pass","Yard Line Zone","0-20"),0),"##0%") -> 33%
B4: =TEXT(GETPIVOTDATA("Sum of Attempts",Refresh!$A$47,"Play Type","Run"),"##0")&"/"&TEXT(GETPIVOTDATA("Sum of Attempts",Refresh!$A$47),"##0") -> 271/376 | G4: =TEXT(IFERROR(GETPIVOTDATA("Count of Attempts",Refresh!$A$68,"Down",1,"Play Type","Run"),0),"##0")&"/"&TEXT(IFERROR(GETPIVOTDATA("Count of Attempts",Refresh!$A$68,"Down",1),0),"##0") -> 124/158 | H4: =TEXT(IFERROR(GETPIVOTDATA("Count of Attempts",Refresh!$A$68,"Down",1,"Play Type","Pass"),0),"##0")&"/"&TEXT(IFERROR(GETPIVOTDATA("Count of Attempts",Refresh!$A$68,"Down",1),0),"##0") -> 34/158 | K4: =TEXT(IFERROR(GETPIVOTDATA("Count of Attempts",Refresh!$A$148,"Play Type","Run","D&D","01: 1st & 10+"),0),"##0")&"/"&GETPIVOTDATA("Count of Attempts",Refresh!$A$148,"D&D","01: 1st & 10+") -> 61/77 | L4: =TEXT(IFERROR(GETPIVOTDATA("Count of Attempts",Refresh!$A$148,"Play Type","Pass","D&D","01: 1st & 10+"),0),"##0")&"/"&GETPIVOTDATA("Count of Attempts",Refresh!$A$148,"D&D","01: 1st & 10+") -> 16/77 | O4: =TEXT(IFERROR(GETPIVOTDATA("Count of Attempts",Refresh!$A$125,"Play Type","Run","Yard Line Zone","0-20"),0),"##0")&"/"&TEXT(IFERROR(GETPIVOTDATA("Count of Attempts",Refresh!$A$125,"Yard Line Zone","0-20"),0),"##0") -> 22/33 | P4: =TEXT(IFERROR(GETPIVOTDATA("Count of Attempts",Refresh!$A$125,"Play Type","Pass","Yard Line Zone","0-20"),0),"##0")&"/"&TEXT(IFERROR(GETPIVOTDATA("Count of Attempts",Refresh!$A$125,"Yard Line Zone","0-20"),0),"##0") -> 11/33
A5: Pass | B5: =TEXT(IFERROR(GETPIVOTDATA("Count of Play",Refresh!$A$47,"Play Type","Pass"),0),"##0%") -> 28% | C5: =TEXT(GETPIVOTDATA("Yards ",Refresh!$A$47,"Play Type","Pass"),"#,##0") -> 235 | D5: =TEXT(IFERROR(GETPIVOTDATA("Sum of Yds per Att",Refresh!$A$47,"Play Type","Pass"),0),"###0.0") -> 2.2 | F5: 2nd | G5: =TEXT(IFERROR(GETPIVOTDATA("% Attempts",Refresh!$A$68,"Down",2,"Play Type","Run"),0),"##0%") -> 77% | H5: =TEXT(IFERROR(GETPIVOTDATA("% Attempts",Refresh!$A$68,"Down",2,"Play Type","Pass"),0),"##0%") -> 23% | J5: 1st & < 10 | K5: =TEXT(IFERROR(GETPIVOTDATA("% Attempts",Refresh!$A$148,"Play Type","Run","D&D","02: 1st & < 10"),0),"##0%") -> 83% | L5: =TEXT(IFERROR(GETPIVOTDATA("% Attempts",Refresh!$A$148,"Play Type","Pass","D&D","02: 1st & < 10"),0),"##0%") -> 17% | N5: 21 - 49 | O5: =TEXT(IFERROR(GETPIVOTDATA("% Attempts",Refresh!$A$125,"Play Type","Run","Yard Line Zone","21-49"),0),"##0%") -> 71% | P5: =TEXT(IFERROR(GETPIVOTDATA("% Attempts",Refresh!$A$125,"Play Type","Pass","Yard Line Zone","21-49"),0),"##0%") -> 29%
B6: =TEXT(GETPIVOTDATA("Sum of Attempts",Refresh!$A$47,"Play Type","Pass"),"##0")&"/"&TEXT(GETPIVOTDATA("Sum of Attempts",Refresh!$A$47),"##0") -> 105/376 | G6: =TEXT(IFERROR(GETPIVOTDATA("Count of Attempts",Refresh!$A$68,"Down",2,"Play Type","Run"),0),"##0")&"/"&TEXT(IFERROR(GETPIVOTDATA("Count of Attempts",Refresh!$A$68,"Down",2),0),"##0") -> 99/128 | H6: =TEXT(IFERROR(GETPIVOTDATA("Count of Attempts",Refresh!$A$68,"Down",2,"Play Type","Pass"),0),"##0")&"/"&TEXT(IFERROR(GETPIVOTDATA("Count of Attempts",Refresh!$A$68,"Down",2),0),"##0") -> 29/128 | K6: =TEXT(IFERROR(GETPIVOTDATA("Count of Attempts",Refresh!$A$148,"Play Type","Run","D&D","02: 1st & < 10"),0),"##0")&"/"&GETPIVOTDATA("Count of Attempts",Refresh!$A$148,"D&D","02: 1st & < 10") -> 5/6 | L6: =TEXT(IFERROR(GETPIVOTDATA("Count of Attempts",Refresh!$A$148,"Play Type","Pass","D&D","02: 1st & < 10"),0),"##0")&"/"&GETPIVOTDATA("Count of Attempts",Refresh!$A$148,"D&D","02: 1st & < 10") -> 1/6 | O6: =TEXT(IFERROR(GETPIVOTDATA("Count of Attempts",Refresh!$A$125,"Play Type","Run","Yard Line Zone","21-49"),0),"##0")&"/"&TEXT(IFERROR(GETPIVOTDATA("Count of Attempts",Refresh!$A$125,"Yard Line Zone","21-49"),0),"##0") -> 123/173 | P6: =TEXT(IFERROR(GETPIVOTDATA("Count of Attempts",Refresh!$A$125,"Play Type","Pass","Yard Line Zone","21-49"),0),"##0")&"/"&TEXT(IFERROR(GETPIVOTDATA("Count of Attempts",Refresh!$A$125,"Yard Line Zone","21-49"),0),"##0") -> 50/173
F7: 3rd | G7: =TEXT(IFERROR(GETPIVOTDATA("% Attempts",Refresh!$A$68,"Down",3,"Play Type","Run"),0),"##0%") -> 56% | H7: =TEXT(IFERROR(GETPIVOTDATA("% Attempts",Refresh!$A$68,"Down",3,"Play Type","Pass"),0),"##0%") -> 44% | J7: 2nd & 8+ | K7: =TEXT(IFERROR(GETPIVOTDATA("% Attempts",Refresh!$A$148,"Play Type","Run","D&D","03: 2nd & 8+"),0),"##0%") -> 68% | L7: =TEXT(IFERROR(GETPIVOTDATA("% Attempts",Refresh!$A$148,"Play Type","Pass","D&D","03: 2nd & 8+"),0),"##0%") -> 33% | N7: 50 - 21 | O7: =TEXT(IFERROR(GETPIVOTDATA("% Attempts",Refresh!$A$125,"Play Type","Run","Yard Line Zone","50-21"),0),"##0%") -> 69% | P7: =TEXT(IFERROR(GETPIVOTDATA("% Attempts",Refresh!$A$125,"Play Type","Pass","Yard Line Zone","50-21"),0),"##0%") -> 31%
G8: =TEXT(IFERROR(GETPIVOTDATA("Count of Attempts",Refresh!$A$68,"Down",3,"Play Type","Run"),0),"##0")&"/"&TEXT(IFERROR(GETPIVOTDATA("Count of Attempts",Refresh!$A$68,"Down",3),0),"##0") -> 44/79 | H8: =TEXT(IFERROR(GETPIVOTDATA("Count of Attempts",Refresh!$A$68,"Down",3,"Play Type","Pass"),0),"##0")&"/"&TEXT(IFERROR(GETPIVOTDATA("Count of Attempts",Refresh!$A$68,"Down",3),0),"##0") -> 35/79 | K8: =TEXT(IFERROR(GETPIVOTDATA("Count of Attempts",Refresh!$A$148,"Play Type","Run","D&D","03: 2nd & 8+"),0),"##0")&"/"&GETPIVOTDATA("Count of Attempts",Refresh!$A$148,"D&D","03: 2nd & 8+") -> 27/40 | L8: =TEXT(IFERROR(GETPIVOTDATA("Count of Attempts",Refresh!$A$148,"Play Type","Pass","D&D","03: 2nd & 8+"),0),"##0")&"/"&GETPIVOTDATA("Count of Attempts",Refresh!$A$148,"D&D","03: 2nd & 8+") -> 13/40 | O8: =TEXT(IFERROR(GETPIVOTDATA("Count of Attempts",Refresh!$A$125,"Play Type","Run","Yard Line Zone","50-21"),0),"##0")&"/"&TEXT(IFERROR(GETPIVOTDATA("Count of Attempts",Refresh!$A$125,"Yard Line Zone","50-21"),0),"##0") -> 82/118 | P8: =TEXT(IFERROR(GETPIVOTDATA("Count of Attempts",Refresh!$A$125,"Play Type","Pass","Yard Line Zone","50-21"),0),"##0")&"/"&TEXT(IFERROR(GETPIVOTDATA("Count of Attempts",Refresh!$A$125,"Yard Line Zone","50-21"),0),"##0") -> 36/118
A9: Strength | F9: 4th | G9: =TEXT(IFERROR(GETPIVOTDATA("% Attempts",Refresh!$A$68,"Down",4,"Play Type","Run"),0),"##0%") -> 36% | H9: =TEXT(IFERROR(GETPIVOTDATA("% Attempts",Refresh!$A$68,"Down",4,"Play Type","Pass"),0),"##0%") -> 64% | J9: 2nd & 4 - 7 | K9: =TEXT(IFERROR(GETPIVOTDATA("% Attempts",Refresh!$A$148,"Play Type","Run","D&D","04: 2nd & 4 - 7"),0),"##0%") -> 95% | L9: =TEXT(IFERROR(GETPIVOTDATA("% Attempts",Refresh!$A$148,"Play Type","Pass","D&D","04: 2nd & 4 - 7"),0),"##0%") -> 5% | N9: Red Zone | O9: =TEXT(IFERROR(GETPIVOTDATA("% Attempts",Refresh!$A$125,"Play Type","Run","Yard Line Zone","Red Zone"),0),"##0%") -> 85% | P9: =TEXT(IFERROR(GETPIVOTDATA("% Attempts",Refresh!$A$125,"Play Type","Pass","Yard Line Zone","Red Zone"),0),"##0%") -> 15%
C10: Yards | D10: Avg | G10: =TEXT(IFERROR(GETPIVOTDATA("Count of Attempts",Refresh!$A$68,"Down",4,"Play Type","Run"),0),"##0")&"/"&TEXT(IFERROR(GETPIVOTDATA("Count of Attempts",Refresh!$A$68,"Down",4),0),"##0") -> 4/11 | H10: =TEXT(IFERROR(GETPIVOTDATA("Count of Attempts",Refresh!$A$68,"Down",4,"Play Type","Pass"),0),"##0")&"/"&TEXT(IFERROR(GETPIVOTDATA("Count of Attempts",Refresh!$A$68,"Down",4),0),"##0") -> 7/11 | K10: =TEXT(IFERROR(GETPIVOTDATA("Count of Attempts",Refresh!$A$148,"Play Type","Run","D&D","04: 2nd & 4 - 7"),0),"##0")&"/"&GETPIVOTDATA("Count of Attempts",Refresh!$A$148,"D&D","04: 2nd & 4 - 7") -> 18/19 | L10: =TEXT(IFERROR(GETPIVOTDATA("Count of Attempts",Refresh!$A$148,"Play Type","Pass","D&D","04: 2nd & 4 - 7"),0),"##0")&"/"&GETPIVOTDATA("Count of Attempts",Refresh!$A$148,"D&D","04: 2nd & 4 - 7") -> 1/19 | O10: =TEXT(IFERROR(GETPIVOTDATA("Count of Attempts",Refresh!$A$125,"Play Type","Run","Yard Line Zone","Red Zone"),0),"##0")&"/"&TEXT(IFERROR(GETPIVOTDATA("Count of Attempts",Refresh!$A$125,"Yard Line Zone","Red Zone"),0),"##0") -> 39/46 | P10: =TEXT(IFERROR(GETPIVOTDATA("Count of Attempts",Refresh!$A$125,"Play Type","Pass","Yard Line Zone","Red Zone"),0),"##0")&"/"&TEXT(IFERROR(GETPIVOTDATA("Count of Attempts",Refresh!$A$125,"Yard Line Zone","Red Zone"),0),"##0") -> 7/46
A11: Left | B11: =TEXT(IFERROR(GETPIVOTDATA("Sum of Attempts",Refresh!$A$97,"Strength","L"),0),"##0%") -> 0% | C11: =TEXT(IFERROR(GETPIVOTDATA("Sum of Yards",Refresh!$A$97,"Strength","L"),0),"###0") -> 0 | D11: =TEXT(IFERROR(GETPIVOTDATA("Sum of Yrd per Att/",Refresh!$A$97,"Strength","L"),0),"###0.0") -> 0.0 | F11: Total | G11: =TEXT(IFERROR(GETPIVOTDATA("% Attempts",Refresh!$A$68,"Play Type","Run"),0),"##0%") -> 72% | H11: =TEXT(IFERROR(GETPIVOTDATA("% Attempts",Refresh!$A$68,"Play Type","Pass"),0),"##0%") -> 28% | J11: 2nd & < 4 | K11: =TEXT(IFERROR(GETPIVOTDATA("% Attempts",Refresh!$A$148,"Play Type","Run","D&D","05: 2nd & < 4"),0),"##0%") -> 89% | L11: =TEXT(IFERROR(GETPIVOTDATA("% Attempts",Refresh!$A$148,"Play Type","Pass","D&D","05: 2nd & < 4"),0),"##0%") -> 11% | N11: Goal Line | O11: =TEXT(IFERROR(GETPIVOTDATA("% Attempts",Refresh!$A$125,"Play Type","Run","Yard Line Zone","Goal Line"),0),"##0%") -> 83% | P11: =TEXT(IFERROR(GETPIVOTDATA("% Attempts",Refresh!$A$125,"Play Type","Pass","Yard Line Zone","Goal Line"),0),"##0%") -> 17%
B12: =TEXT(IFERROR(GETPIVOTDATA("Sum of Attempts2",Refresh!$A$97,"Strength","L"),0),"##0")&"/"&TEXT(IFERROR(GETPIVOTDATA("Sum of Attempts2",Refresh!$A$97),0),"##0") -> 0/0 | G12: =TEXT(IFERROR(GETPIVOTDATA("Count of Attempts",Refresh!$A$68,"Play Type","Run"),0),"##0")&"/"&TEXT(IFERROR(GETPIVOTDATA("Count of Attempts",Refresh!$A$68),0),"##0") -> 271/376 | H12: =TEXT(IFERROR(GETPIVOTDATA("Count of Attempts",Refresh!$A$68,"Play Type","Pass"),0),"##0")&"/"&TEXT(IFERROR(GETPIVOTDATA("Count of Attempts",Refresh!$A$68),0),"##0") -> 105/376 | K12: =TEXT(IFERROR(GETPIVOTDATA("Count of Attempts",Refresh!$A$148,"Play Type","Run","D&D","05: 2nd & < 4"),0),"##0")&"/"&GETPIVOTDATA("Count of Attempts",Refresh!$A$148,"D&D","05: 2nd & < 4") -> 8/9 | L12: =TEXT(IFERROR(GETPIVOTDATA("Count of Attempts",Refresh!$A$148,"Play Type","Pass","D&D","05: 2nd & < 4"),0),"##0")&"/"&GETPIVOTDATA("Count of Attempts",Refresh!$A$148,"D&D","05: 2nd & < 4") -> 1/9 | O12: =TEXT(IFERROR(GETPIVOTDATA("Count of Attempts",Refresh!$A$125,"Play Type","Run","Yard Line Zone","Goal Line"),0),"##0")&"/"&TEXT(IFERROR(GETPIVOTDATA("Count of Attempts",Refresh!$A$125,"Yard Line Zone","Goal Line"),0),"##0") -> 5/6 | P12: =TEXT(IFERROR(GETPIVOTDATA("Count of Attempts",Refresh!$A$125,"Play Type","Pass","Yard Line Zone","Goal Line"),0),"##0")&"/"&TEXT(IFERROR(GETPIVOTDATA("Count of Attempts",Refresh!$A$125,"Yard Line Zone","Goal Line"),0),"##0") -> 1/6
A13: Right | B13: =TEXT(IFERROR(GETPIVOTDATA("Sum of Attempts",Refresh!$A$97,"Strength","R"),0),"##0%") -> 0% | C13: =TEXT(IFERROR(GETPIVOTDATA("Sum of Yards",Refresh!$A$97,"Strength","R"),0),"###0") -> 0 | D13: =TEXT(IFERROR(GETPIVOTDATA("Sum of Yrd per Att/",Refresh!$A$97,"Strength","R"),0),"###0.0") -> 0.0 | J13: 3rd & 8+ | K13: =TEXT(IFERROR(GETPIVOTDATA("% Attempts",Refresh!$A$148,"Play Type","Run","D&D","06: 3rd & 8+"),0),"##0%") -> 59% | L13: =TEXT(IFERROR(GETPIVOTDATA("% Attempts",Refresh!$A$148,"Play Type","Pass","D&D","06: 3rd & 8+"),0),"##0%") -> 41%
B14: =TEXT(IFERROR(GETPIVOTDATA("Sum of Attempts2",Refresh!$A$97,"Strength","R"),0),"##0")&"/"&TEXT(IFERROR(GETPIVOTDATA("Sum of Attempts2",Refresh!$A$97),0),"##0") -> 0/0 | K14: =TEXT(IFERROR(GETPIVOTDATA("Count of Attempts",Refresh!$A$148,"Play Type","Run","D&D","06: 3rd & 8+"),0),"##0")&"/"&GETPIVOTDATA("Count of Attempts",Refresh!$A$148,"D&D","06: 3rd & 8+") -> 13/22 | L14: =TEXT(IFERROR(GETPIVOTDATA("Count of Attempts",Refresh!$A$148,"Play Type","Pass","D&D","06: 3rd & 8+"),0),"##0")&"/"&GETPIVOTDATA("Count of Attempts",Refresh!$A$148,"D&D","06: 3rd & 8+") -> 9/22
A15: BAL | B15: =TEXT(IFERROR(GETPIVOTDATA("Sum of Attempts",Refresh!$A$97,"Strength","BAL"),0),"##0%") -> 0% | C15: =TEXT(IFERROR(GETPIVOTDATA("Sum of Yards",Refresh!$A$97,"Strength","BAL"),0),"###0") -> 0 | D15: =TEXT(IFERROR(GETPIVOTDATA("Sum of Yrd per Att/",Refresh!$A$97,"Strength","BAL"),0),"###0.0") -> 0.0 | J15: 3rd & 4 - 7 | K15: =TEXT(IFERROR(GETPIVOTDATA("% Attempts",Refresh!$A$148,"Play Type","Run","D&D","07: 3rd & 4 - 7"),0),"##0%") -> 67% | L15: =TEXT(IFERROR(GETPIVOTDATA("% Attempts",Refresh!$A$148,"Play Type","Pass","D&D","07: 3rd & 4 - 7"),0),"##0%") -> 33%
B16: =TEXT(IFERROR(GETPIVOTDATA("Sum of Attempts2",Refresh!$A$97,"Strength","BAL"),0),"##0")&"/"&TEXT(IFERROR(GETPIVOTDATA("Sum of Attempts2",Refresh!$A$97),0),"##0") -> 0/0 | K16: =TEXT(IFERROR(GETPIVOTDATA("Count of Attempts",Refresh!$A$148,"Play Type","Run","D&D","01: 1st & 10+"),0),"##0")&"/"&GETPIVOTDATA("Count of Attempts",Refresh!$A$148,"D&D","01: 1st & 10+") -> 61/77 | L16: =TEXT(IFERROR(GETPIVOTDATA("Count of Attempts",Refresh!$A$148,"Play Type","Pass","D&D","01: 1st & 10+"),0),"##0")&"/"&GETPIVOTDATA("Count of Attempts",Refresh!$A$148,"D&D","01: 1st & 10+") -> 16/77 | N16: Field vs Boundry
A17: Strong | B17: =TEXT(IFERROR(GETPIVOTDATA("Sum of Attempts",Refresh!$A$83,"Strength1","Strong"),0),"##0%") -> 0% | C17: =TEXT(IFERROR(GETPIVOTDATA("Sum of Yards",Refresh!$A$83,"Strength1","Strong"),0),"#,##0") -> 0 | D17: =TEXT(IFERROR(GETPIVOTDATA("Sum of Yrd per Att/",Refresh!$A$83,"Strength1","Strong"),0),"#0.0") -> 0.0 | J17: 3rd & < 4 | K17: =TEXT(IFERROR(GETPIVOTDATA("% Attempts",Refresh!$A$148,"Play Type","Run","D&D","08: 3rd & < 4"),0),"##0%") -> 100% | L17: =TEXT(IFERROR(GETPIVOTDATA("% Attempts",Refresh!$A$148,"Play Type","Pass","D&D","08: 3rd & < 4"),0),"##0%") -> 0%
B18: =TEXT(IFERROR(GETPIVOTDATA("Sum of Attempts2",Refresh!$A$83,"Strength1","Strong"),0),"##0")&"/"&TEXT(IFERROR(GETPIVOTDATA("Sum of Attempts2",Refresh!$A$83),0),"##0") -> 0/0 | K18: =TEXT(IFERROR(GETPIVOTDATA("Count of Attempts",Refresh!$A$148,"Play Type","Run","D&D","08: 3rd & < 4"),0),"##0")&"/"&GETPIVOTDATA("Count of Attempts",Refresh!$A$148,"D&D","08: 3rd & < 4") -> 9/9 | L18: =TEXT(IFERROR(GETPIVOTDATA("Count of Attempts",Refresh!$A$148,"Play Type","Pass","D&D","08: 3rd & < 4"),0),"##0")&"/"&GETPIVOTDATA("Count of Attempts",Refresh!$A$148,"D&D","08: 3rd & < 4") -> 0/9 | N18: Run | O18: Field | P18: =TEXT(IFERROR(GETPIVOTDATA("% Attempts",Refresh!$A$111,"Play Type","Run","Boundry","Field"),0),"##0%") -> 61%
A19: Weak | B19: =TEXT(IFERROR(GETPIVOTDATA("Sum of Attempts",Refresh!$A$83,"Strength1","Weak"),0),"##0%") -> 0% | C19: =TEXT(IFERROR(GETPIVOTDATA("Sum of Yards",Refresh!$A$83,"Strength1","Weak"),0),"#,##0") -> 0 | D19: =TEXT(IFERROR(GETPIVOTDATA("Sum of Yrd per Att/",Refresh!$A$83,"Strength1","Weak"),0),"#0.0") -> 0.0 | J19: 4th & 2+ | K19: =TEXT(IFERROR(GETPIVOTDATA("% Attempts",Refresh!$A$148,"Play Type","Run","D&D","09: 4th & 2+"),0),"##0%") -> 50% | L19: =TEXT(IFERROR(GETPIVOTDATA("% Attempts",Refresh!$A$148,"Play Type","Pass","D&D","09: 4th & 2+"),0),"##0%") -> 50% | O19: (Wide) | P19: =TEXT(IFERROR(GETPIVOTDATA("Count of Attempts",Refresh!$A$111,"Play Type","Run","Boundry","Field"),0),"##0")&"/"&TEXT(IFERROR(GETPIVOTDATA("Count of Attempts",Refresh!$A$111:$A$111,"Play Type","Run"),0),"###0") -> 132/218
B20: =TEXT(IFERROR(GETPIVOTDATA("Sum of Attempts2",Refresh!$A$83,"Strength1","Weak"),0),"##0")&"/"&TEXT(IFERROR(GETPIVOTDATA("Sum of Attempts2",Refresh!$A$83),0),"##0") -> 0/0 | K20: =TEXT(IFERROR(GETPIVOTDATA("Count of Attempts",Refresh!$A$148,"Play Type","Run","D&D","09: 4th & 2+"),0),"##0")&"/"&GETPIVOTDATA("Count of Attempts",Refresh!$A$148,"D&D","09: 4th & 2+") -> 4/8 | L20: =TEXT(IFERROR(GETPIVOTDATA("Count of Attempts",Refresh!$A$148,"Play Type","Pass","D&D","09: 4th & 2+"),0),"##0")&"/"&GETPIVOTDATA("Count of Attempts",Refresh!$A$148,"D&D","09: 4th & 2+") -> 4/8 | O20: Boundry | P20: =TEXT(IFERROR(GETPIVOTDATA("% Attempts",Refresh!$A$111,"Play Type","Run","Boundry","Boundry"),0),"##0%") -> 39%
A21: BAL | B21: =TEXT(IFERROR(GETPIVOTDATA("Sum of Attempts",Refresh!$A$83,"Strength1","BAL"),0),"##0%") -> 0% | C21: =TEXT(IFERROR(GETPIVOTDATA("Sum of Yards",Refresh!$A$83,"Strength1","BAL"),0),"#,##0") -> 0 | D21: =TEXT(IFERROR(GETPIVOTDATA("Sum of Yrd per Att/",Refresh!$A$83,"Strength1","BAL"),0),"#0.0") -> 0.0 | J21: 4th & ≤ 2 | K21: =TEXT(IFERROR(GETPIVOTDATA("% Attempts",Refresh!$A$148,"Play Type","Run","D&D","10: 4th & < 2"),0),"##0%") -> 0% | L21: =TEXT(IFERROR(GETPIVOTDATA("% Attempts",Refresh!$A$148,"Play Type","Pass","D&D","10: 4th & < 2"),0),"##0%") -> 0% | O21: (Short) | P21: =TEXT(IFERROR(GETPIVOTDATA("Count of Attempts",Refresh!$A$111,"Play Type","Run","Boundry","Boundry"),0),"##0")&"/"&TEXT(IFERROR(GETPIVOTDATA("Count of Attempts",Refresh!$A$111:$A$111,"Play Type","Run"),0),"###0") -> 86/218
B22: =TEXT(IFERROR(GETPIVOTDATA("Sum of Attempts2",Refresh!$A$83,"Strength1","BAL"),0),"##0")&"/"&TEXT(IFERROR(GETPIVOTDATA("Sum of Attempts2",Refresh!$A$83),0),"##0") -> 0/0 | K22: =TEXT(IFERROR(GETPIVOTDATA("Count of Attempts",Refresh!$A$148,"Play Type","Run","D&D","10: 4th & < 2"),0),"##0")&"/"&GETPIVOTDATA("Count of Attempts",Refresh!$A$148,"D&D","10: 4th & < 2") -> #REF! | L22: =TEXT(IFERROR(GETPIVOTDATA("Count of Attempts",Refresh!$A$148,"Play Type","Pass","D&D","10: 4th & < 2"),0),"##0")&"/"&GETPIVOTDATA("Count of Attempts",Refresh!$A$148,"D&D","10: 4th & < 2") -> #REF! | N22: Pass | O22: Field | P22: =TEXT(IFERROR(GETPIVOTDATA("% Attempts",Refresh!$A$111,"Play Type","Pass","Boundry","Field"),0),"##0%") -> 81%
O23: (Wide) | P23: =TEXT(IFERROR(GETPIVOTDATA("Count of Attempts",Refresh!$A$111,"Play Type","Pass","Boundry","Field"),0),"##0")&"/"&TEXT(IFERROR(GETPIVOTDATA("Count of Attempts",Refresh!$A$111:$A$111,"Play Type","Pass"),0),"###0") -> 51/63
O24: Boundry | P24: =TEXT(IFERROR(GETPIVOTDATA("% Attempts",Refresh!$A$111,"Play Type","Pass","Boundry","Boundry"),0),"##0%") -> 19%
A25: Down & Distance | O25: (Short) | P25: =TEXT(IFERROR(GETPIVOTDATA("Count of Attempts",Refresh!$A$111,"Play Type","Pass","Boundry","Boundry"),0),"##0")&"/"&TEXT(IFERROR(GETPIVOTDATA("Count of Attempts",Refresh!$A$111:$A$111,"Play Type","Pass"),0),"###0") -> 12/63
B26: 0-20 | D26: 21-49 | F26: 50-21 | H26: Red Zone | J26: Goal Line | N26: Total | O26: Field | P26: =TEXT(IFERROR(GETPIVOTDATA("% Attempts",Refresh!$A$111,"Boundry","Field"),0),"##0%") -> 65%
B27: Run | C27: Pass | D27: Run | E27: Pass | F27: Run | G27: Pass | H27: Run | I27: Pass | J27: Run | K27: Pass | O27: (Wide) | P27: =TEXT(IFERROR(GETPIVOTDATA("Count of Attempts",Refresh!$A$111,"Boundry","Field"),0),"##0")&"/"&TEXT(IFERROR(GETPIVOTDATA("Count of Attempts",Refresh!$A$111),0),"##0") -> 183/281
A28: 1st & 10+ | B28: =TEXT(IFERROR(GETPIVOTDATA("% Attempts",Refresh!$A$125,"Play Type","Run","D&D","01: 1st & 10+","Yard Line Zone","0-20"),0),"##0%") -> 75% | C28: =TEXT(IFERROR(GETPIVOTDATA("% Attempts",Refresh!$A$125,"Play Type","Pass","D&D","01: 1st & 10+","Yard Line Zone","0-20"),0),"##0%") -> 25% | D28: =TEXT(IFERROR(GETPIVOTDATA("% Attempts",Refresh!$A$125,"Play Type","Run","D&D","01: 1st & 10+","Yard Line Zone","21-49"),0),"##0%") -> 80% | E28: =TEXT(IFERROR(GETPIVOTDATA("% Attempts",Refresh!$A$125,"Play Type","Pass","D&D","01: 1st & 10+","Yard Line Zone","21-49"),0),"##0%") -> 20% | F28: =TEXT(IFERROR(GETPIVOTDATA("% Attempts",Refresh!$A$125,"Play Type","Run","D&D","01: 1st & 10+","Yard Line Zone","50-21"),0),"##0%") -> 79% | G28: =TEXT(IFERROR(GETPIVOTDATA("% Attempts",Refresh!$A$125,"Play Type","Pass","D&D","01: 1st & 10+","Yard Line Zone","50-21"),0),"##0%") -> 21% | H28: =TEXT(IFERROR(GETPIVOTDATA("% Attempts",Refresh!$A$125,"Play Type","Run","D&D","01: 1st & 10+","Yard Line Zone","Red Zone"),0),"##0%") -> 100% | I28: =TEXT(IFERROR(GETPIVOTDATA("% Attempts",Refresh!$A$125,"Play Type","Pass","D&D","01: 1st & 10+","Yard Line Zone","Red Zone"),0),"##0%") -> 0% | J28: =TEXT(IFERROR(GETPIVOTDATA("% Attempts",Refresh!$A$125,"Play Type","Run","D&D","01: 1st & 10+","Yard Line Zone","Goal Line"),0),"##0%") -> 0% | K28: =TEXT(IFERROR(GETPIVOTDATA("% Attempts",Refresh!$A$125,"Play Type","Pass","D&D","01: 1st & 10+","Yard Line Zone","Goal Line"),0),"##0%") -> 100% | O28: Boundry | P28: =TEXT(IFERROR(GETPIVOTDATA("% Attempts",Refresh!$A$111,"Boundry","Boundry"),0),"##0%") -> 35%
B29: =Refresh!AT129 -> 0 | C29: =Refresh!AU129 -> 0 | D29: =Refresh!AV129 -> 0 | E29: =Refresh!AW129 -> 0 | F29: =Refresh!AX129 -> 0 | G29: =Refresh!AY129 -> 0 | H29: =Refresh!AZ129 -> 0 | I29: =Refresh!BA129 -> 0 | ... K29: =Refresh!BC129 -> 0 | O29: (Short) | P29: =TEXT(IFERROR(GETPIVOTDATA("Count of Attempts",Refresh!$A$111,"Boundry","Boundry"),0),"##0")&"/"&TEXT(IFERROR(GETPIVOTDATA("Count of Attempts",Refresh!$A$111),0),"##0") -> 98/281
A30: 1st & < 10 | B30: =TEXT(IFERROR(GETPIVOTDATA("% Attempts",Refresh!$A$125,"Play Type","Run","D&D","02: 1st & < 10","Yard Line Zone","0-20"),0),"##0%") -> 0% | C30: =TEXT(IFERROR(GETPIVOTDATA("% Attempts",Refresh!$A$125,"Play Type","Pass","D&D","02: 1st & < 10","Yard Line Zone","0-20"),0),"##0%") -> 0% | D30: =TEXT(IFERROR(GETPIVOTDATA("% Attempts",Refresh!$A$125,"Play Type","Run","D&D","02: 1st & < 10","Yard Line Zone","21-49"),0),"##0%") -> 100% | E30: =TEXT(IFERROR(GETPIVOTDATA("% Attempts",Refresh!$A$125,"Play Type","Pass","D&D","02: 1st & < 10","Yard Line Zone","21-49"),0),"##0%") -> 0% | F30: =TEXT(IFERROR(GETPIVOTDATA("% Attempts",Refresh!$A$125,"Play Type","Run","D&D","02: 1st & < 10","Yard Line Zone","50-21"),0),"##0%") -> 100% | G30: =TEXT(IFERROR(GETPIVOTDATA("% Attempts",Refresh!$A$125,"Play Type","Pass","D&D","02: 1st & < 10","Yard Line Zone","50-21"),0),"##0%") -> 0% | H30: =TEXT(IFERROR(GETPIVOTDATA("% Attempts",Refresh!$A$125,"Play Type","Run","D&D","02: 1st & < 10","Yard Line Zone","Red Zone"),0),"##0%") -> 75% | I30: =TEXT(IFERROR(GETPIVOTDATA("% Attempts",Refresh!$A$125,"Play Type","Pass","D&D","02: 1st & < 10","Yard Line Zone","Red Zone"),0),"##0%") -> 25% | J30: =TEXT(IFERROR(GETPIVOTDATA("% Attempts",Refresh!$A$125,"Play Type","Run","D&D","02: 1st & < 10","Yard Line Zone","Goal Line"),0),"##0%") -> 0% | K30: =TEXT(IFERROR(GETPIVOTDATA("% Attempts",Refresh!$A$125,"Play Type","Pass","D&D","02: 1st & < 10","Yard Line Zone","Goal Line"),0),"##0%") -> 0%
B31: =Refresh!AT130 -> 0 | C31: =Refresh!AU130 -> 0 | D31: =Refresh!AV130 -> 0 | E31: =Refresh!AW130 -> 0 | F31: =Refresh!AX130 -> 0 | G31: =Refresh!AY130 -> 0 | H31: =Refresh!AZ130 -> 0 | I31: =Refresh!BA130 -> 0 | ... K31: =Refresh!BC130 -> 0
A32: 2nd & 8+ | B32: =TEXT(IFERROR(GETPIVOTDATA("% Attempts",Refresh!$A$125,"Play Type","Run","D&D","03: 2nd & 8+","Yard Line Zone","0-20"),0),"##0%") -> 71% | C32: =TEXT(IFERROR(GETPIVOTDATA("% Attempts",Refresh!$A$125,"Play Type","Pass","D&D","03: 2nd & 8+","Yard Line Zone","0-20"),0),"##0%") -> 29% | D32: =TEXT(IFERROR(GETPIVOTDATA("% Attempts",Refresh!$A$125,"Play Type","Run","D&D","03: 2nd & 8+","Yard Line Zone","21-49"),0),"##0%") -> 69% | E32: =TEXT(IFERROR(GETPIVOTDATA("% Attempts",Refresh!$A$125,"Play Type","Pass","D&D","03: 2nd & 8+","Yard Line Zone","21-49"),0),"##0%") -> 31% | F32: =TEXT(IFERROR(GETPIVOTDATA("% Attempts",Refresh!$A$125,"Play Type","Run","D&D","03: 2nd & 8+","Yard Line Zone","50-21"),0),"##0%") -> 64% | G32: =TEXT(IFERROR(GETPIVOTDATA("% Attempts",Refresh!$A$125,"Play Type","Pass","D&D","03: 2nd & 8+","Yard Line Zone","50-21"),0),"##0%") -> 36% | H32: =TEXT(IFERROR(GETPIVOTDATA("% Attempts",Refresh!$A$125,"Play Type","Run","D&D","03: 2nd & 8+","Yard Line Zone","Red Zone"),0),"##0%") -> 60% | I32: =TEXT(IFERROR(GETPIVOTDATA("% Attempts",Refresh!$A$125,"Play Type","Pass","D&D","03: 2nd & 8+","Yard Line Zone","Red Zone"),0),"##0%") -> 40% | J32: =TEXT(IFERROR(GETPIVOTDATA("% Attempts",Refresh!$A$125,"Play Type","Run","D&D","03: 2nd & 8+","Yard Line Zone","Goal Line"),0),"##0%") -> 100% | K32: =TEXT(IFERROR(GETPIVOTDATA("% Attempts",Refresh!$A$125,"Play Type","Pass","D&D","03: 2nd & 8+","Yard Line Zone","Goal Line"),0),"##0%") -> 0%
B33: =Refresh!AT131 -> 0 | C33: =Refresh!AU131 -> 0 | D33: =Refresh!AV131 -> 0 | E33: =Refresh!AW131 -> 0 | F33: =Refresh!AX131 -> 0 | G33: =Refresh!AY131 -> 0 | H33: =Refresh!AZ131 -> 0 | I33: =Refresh!BA131 -> 0 | ... K33: =Refresh!BC131 -> 0
A34: 2nd & 4 - 7 | B34: =TEXT(IFERROR(GETPIVOTDATA("% Attempts",Refresh!$A$125,"Play Type","Run","D&D","04: 2nd & 4 - 7","Yard Line Zone","0-20"),0),"##0%") -> 100% | C34: =TEXT(IFERROR(GETPIVOTDATA("% Attempts",Refresh!$A$125,"Play Type","Pass","D&D","04: 2nd & 4 - 7","Yard Line Zone","0-20"),0),"##0%") -> 0% | D34: =TEXT(IFERROR(GETPIVOTDATA("% Attempts",Refresh!$A$125,"Play Type","Run","D&D","04: 2nd & 4 - 7","Yard Line Zone","21-49"),0),"##0%") -> 83% | E34: =TEXT(IFERROR(GETPIVOTDATA("% Attempts",Refresh!$A$125,"Play Type","Pass","D&D","04: 2nd & 4 - 7","Yard Line Zone","21-49"),0),"##0%") -> 17% | F34: =TEXT(IFERROR(GETPIVOTDATA("% Attempts",Refresh!$A$125,"Play Type","Run","D&D","04: 2nd & 4 - 7","Yard Line Zone","50-21"),0),"##0%") -> 100% | G34: =TEXT(IFERROR(GETPIVOTDATA("% Attempts",Refresh!$A$125,"Play Type","Pass","D&D","04: 2nd & 4 - 7","Yard Line Zone","50-21"),0),"##0%") -> 0% | H34: =TEXT(IFERROR(GETPIVOTDATA("% Attempts",Refresh!$A$125,"Play Type","Run","D&D","04: 2nd & 4 - 7","Yard Line Zone","Red Zone"),0),"##0%") -> 100% | I34: =TEXT(IFERROR(GETPIVOTDATA("% Attempts",Refresh!$A$125,"Play Type","Pass","D&D","04: 2nd & 4 - 7","Yard Line Zone","Red Zone"),0),"##0%") -> 0% | J34: =TEXT(IFERROR(GETPIVOTDATA("% Attempts",Refresh!$A$125,"Play Type","Run","D&D","04: 2nd & 4 - 7","Yard Line Zone","Goal Line"),0),"##0%") -> 0% | K34: =TEXT(IFERROR(GETPIVOTDATA("% Attempts",Refresh!$A$125,"Play Type","Pass","D&D","04: 2nd & 4 - 7","Yard Line Zone","Goal Line"),0),"##0%") -> 0%
B35: =Refresh!AT132 -> 0 | C35: =Refresh!AU132 -> 0 | D35: =Refresh!AV132 -> 0 | E35: =Refresh!AW132 -> 0 | F35: =Refresh!AX132 -> 0 | G35: =Refresh!AY132 -> 0 | H35: =Refresh!AZ132 -> 0 | I35: =Refresh!BA132 -> 0 | ... K35: =Refresh!BC132 -> 0
A36: 2nd & < 4 | B36: =TEXT(IFERROR(GETPIVOTDATA("% Attempts",Refresh!$A$125,"Play Type","Run","D&D","05: 2nd & < 4","Yard Line Zone","0-20"),0),"##0%") -> 0% | C36: =TEXT(IFERROR(GETPIVOTDATA("% Attempts",Refresh!$A$125,"Play Type","Pass","D&D","05: 2nd & < 4","Yard Line Zone","0-20"),0),"##0%") -> 0% | D36: =TEXT(IFERROR(GETPIVOTDATA("% Attempts",Refresh!$A$125,"Play Type","Run","D&D","05: 2nd & < 4","Yard Line Zone","21-49"),0),"##0%") -> 67% | E36: =TEXT(IFERROR(GETPIVOTDATA("% Attempts",Refresh!$A$125,"Play Type","Pass","D&D","05: 2nd & < 4","Yard Line Zone","21-49"),0),"##0%") -> 33% | F36: =TEXT(IFERROR(GETPIVOTDATA("% Attempts",Refresh!$A$125,"Play Type","Run","D&D","05: 2nd & < 4","Yard Line Zone","50-21"),0),"##0%") -> 100% | G36: =TEXT(IFERROR(GETPIVOTDATA("% Attempts",Refresh!$A$125,"Play Type","Pass","D&D","05: 2nd & < 4","Yard Line Zone","50-21"),0),"##0%") -> 0% | H36: =TEXT(IFERROR(GETPIVOTDATA("% Attempts",Refresh!$A$125,"Play Type","Run","D&D","05: 2nd & < 4","Yard Line Zone","Red Zone"),0),"##0%") -> 100% | I36: =TEXT(IFERROR(GETPIVOTDATA("% Attempts",Refresh!$A$125,"Play Type","Pass","D&D","05: 2nd & < 4","Yard Line Zone","Red Zone"),0),"##0%") -> 0% | J36: =TEXT(IFERROR(GETPIVOTDATA("% Attempts",Refresh!$A$125,"Play Type","Run","D&D","05: 2nd & < 4","Yard Line Zone","Goal Line"),0),"##0%") -> 0% | K36: =TEXT(IFERROR(GETPIVOTDATA("% Attempts",Refresh!$A$125,"Play Type","Pass","D&D","05: 2nd & < 4","Yard Line Zone","Goal Line"),0),"##0%") -> 0%
B37: =Refresh!AT133 -> 0 | C37: =Refresh!AU133 -> 0 | D37: =Refresh!AV133 -> 0 | E37: =Refresh!AW133 -> 0 | F37: =Refresh!AX133 -> 0 | G37: =Refresh!AY133 -> 0 | H37: =Refresh!AZ133 -> 0 | I37: =Refresh!BA133 -> 0 | ... K37: =Refresh!BC133 -> 0
A38: 3rd & 8+ | B38: =TEXT(IFERROR(GETPIVOTDATA("% Attempts",Refresh!$A$125,"Play Type","Run","D&D","06: 3rd & 8+","Yard Line Zone","0-20"),0),"##0%") -> 67% | C38: =TEXT(IFERROR(GETPIVOTDATA("% Attempts",Refresh!$A$125,"Play Type","Pass","D&D","06: 3rd & 8+","Yard Line Zone","0-20"),0),"##0%") -> 33% | D38: =TEXT(IFERROR(GETPIVOTDATA("% Attempts",Refresh!$A$125,"Play Type","Run","D&D","06: 3rd & 8+","Yard Line Zone","21-49"),0),"##0%") -> 67% | E38: =TEXT(IFERROR(GETPIVOTDATA("% Attempts",Refresh!$A$125,"Play Type","Pass","D&D","01: 1st & 10+","Yard Line Zone","21-49"),0),"##0%") -> 20% | F38: =TEXT(IFERROR(GETPIVOTDATA("% Attempts",Refresh!$A$125,"Play Type","Run","D&D","01: 1st & 10+","Yard Line Zone","50-21"),0),"##0%") -> 79% | G38: =TEXT(IFERROR(GETPIVOTDATA("% Attempts",Refresh!$A$125,"Play Type","Pass","D&D","01: 1st & 10+","Yard Line Zone","50-21"),0),"##0%") -> 21% | H38: =TEXT(IFERROR(GETPIVOTDATA("% Attempts",Refresh!$A$125,"Play Type","Run","D&D","01: 1st & 10+","Yard Line Zone","Red Zone"),0),"##0%") -> 100% | I38: =TEXT(IFERROR(GETPIVOTDATA("% Attempts",Refresh!$A$125,"Play Type","Pass","D&D","01: 1st & 10+","Yard Line Zone","Red Zone"),0),"##0%") -> 0% | J38: =TEXT(IFERROR(GETPIVOTDATA("% Attempts",Refresh!$A$125,"Play Type","Run","D&D","01: 1st & 10+","Yard Line Zone","Goal Line"),0),"##0%") -> 0% | K38: =TEXT(IFERROR(GETPIVOTDATA("% Attempts",Refresh!$A$125,"Play Type","Pass","D&D","01: 1st & 10+","Yard Line Zone","Goal Line"),0),"##0%") -> 100%
B39: =Refresh!AT134 -> 0 | C39: =Refresh!AU134 -> 0 | D39: =Refresh!AV134 -> 0 | E39: =Refresh!AW134 -> 0 | F39: =Refresh!AX134 -> 0 | G39: =Refresh!AY134 -> 0 | H39: =Refresh!AZ134 -> 0 | I39: =Refresh!BA134 -> 0 | ... K39: =Refresh!BC134 -> 0
A40: 3rd & 4 - 7 | B40: =TEXT(IFERROR(GETPIVOTDATA("% Attempts",Refresh!$A$125,"Play Type","Run","D&D","07: 3rd & 4 - 7","Yard Line Zone","0-20"),0),"##0%") -> 100% | C40: =TEXT(IFERROR(GETPIVOTDATA("% Attempts",Refresh!$A$125,"Play Type","Pass","D&D","07: 3rd & 4 - 7","Yard Line Zone","0-20"),0),"##0%") -> 0% | D40: =TEXT(IFERROR(GETPIVOTDATA("% Attempts",Refresh!$A$125,"Play Type","Run","D&D","07: 3rd & 4 - 7","Yard Line Zone","21-49"),0),"##0%") -> 67% | E40: =TEXT(IFERROR(GETPIVOTDATA("% Attempts",Refresh!$A$125,"Play Type","Pass","D&D","07: 3rd & 4 - 7","Yard Line Zone","21-49"),0),"##0%") -> 33% | F40: =TEXT(IFERROR(GETPIVOTDATA("% Attempts",Refresh!$A$125,"Play Type","Run","D&D","07: 3rd & 4 - 7","Yard Line Zone","50-21"),0),"##0%") -> 0% | G40: =TEXT(IFERROR(GETPIVOTDATA("% Attempts",Refresh!$A$125,"Play Type","Pass","D&D","07: 3rd & 4 - 7","Yard Line Zone","50-21"),0),"##0%") -> 100% | H40: =TEXT(IFERROR(GETPIVOTDATA("% Attempts",Refresh!$A$125,"Play Type","Run","D&D","07: 3rd & 4 - 7","Yard Line Zone","Red Zone"),0),"##0%") -> 100% | I40: =TEXT(IFERROR(GETPIVOTDATA("% Attempts",Refresh!$A$125,"Play Type","Pass","D&D","07: 3rd & 4 - 7","Yard Line Zone","Red Zone"),0),"##0%") -> 0% | J40: =TEXT(IFERROR(GETPIVOTDATA("% Attempts",Refresh!$A$125,"Play Type","Run","D&D","07: 3rd & 4 - 7","Yard Line Zone","Goal Line"),0),"##0%") -> 0% | K40: =TEXT(IFERROR(GETPIVOTDATA("% Attempts",Refresh!$A$125,"Play Type","Pass","D&D","07: 3rd & 4 - 7","Yard Line Zone","Goal Line"),0),"##0%") -> 0% | S40: v
...

Sheet Enter Numbers Here
A1: Play | B1: ODK | C1: Down | D1: Distance | E1: Yard Line | F1: Gain/Loss | G1: Hash | H1: Strength | I1: Motion | J1: Play Type | K1: Direction | L1: Gap | M1: Attempts | N1: Complete | O1: Pass Zone | P1: Yards | Q1: Direction G | R1: Direction1 | S1: Zone G | T1: Strength1 | U1: Boundry | V1: D&D | W1: Yard Line Zone
F2: =MOD(Table11[[#This Row],[Yard Line]],100)-MOD(E3,100) -> 0 | J2: Pass | K2: R | M2: 0 | N2: 0 | O2: S | P2: 0 | Q2: 2.5 | R2: Right | S2: 0.5 | W2: Goal Line
F3: =MOD(Table11[[#This Row],[Yard Line]],100)-MOD(E4,100) -> 0 | J3: Pass | K3: R | M3: 0 | N3: 0 | O3: M | P3: 0 | Q3: 2.5 | R3: Right | S3: 1.5 | W3: Goal Line
F4: =MOD(Table11[[#This Row],[Yard Line]],100)-MOD(E5,100) -> 0 | J4: Pass | K4: R | M4: 0 | N4: 0 | O4: D | P4: 0 | Q4: 2.5 | R4: Right | S4: 2.5 | W4: Goal Line
F5: =MOD(Table11[[#This Row],[Yard Line]],100)-MOD(E6,100) -> 0 | J5: Pass | K5: L | M5: 0 | N5: 0 | O5: S | P5: 0 | Q5: 0.5 | R5: Left | S5: 0.5 | W5: Goal Line
F6: =MOD(Table11[[#This Row],[Yard Line]],100)-MOD(E7,100) -> 0 | J6: Pass | K6: L | M6: 0 | N6: 0 | O6: M | P6: 0 | Q6: 0.5 | R6: Left | S6: 1.5 | W6: Goal Line
F7: =MOD(Table11[[#This Row],[Yard Line]],100)-MOD(E8,100) -> 0 | J7: Pass | K7: L | M7: 0 | N7: 0 | O7: D | P7: 0 | Q7: 0.5 | R7: Left | S7: 2.5 | W7: Goal Line
F8: =MOD(Table11[[#This Row],[Yard Line]],100)-MOD(E9,100) -> 0 | J8: Pass | K8: M | M8: 0 | N8: 0 | O8: S | P8: 0 | Q8: 1.5 | R8: Middle | S8: 0.5 | W8: Goal Line
F9: =MOD(Table11[[#This Row],[Yard Line]],100)-MOD(E10,100) -> 0 | J9: Pass | K9: M | M9: 0 | N9: 0 | O9: M | P9: 0 | Q9: 1.5 | R9: Middle | S9: 1.5 | W9: Goal Line
F10: =MOD(Table11[[#This Row],[Yard Line]],100)-MOD(E11,100) -> 0 | J10: Pass | K10: M | M10: 0 | N10: 0 | O10: S | P10: 0 | Q10: 1.5 | R10: Middle | S10: 0.5 | W10: Goal Line
F11: =MOD(Table11[[#This Row],[Yard Line]],100)-MOD(E12,100) -> 0 | J11: Run | K11: R | L11: A | M11: 0 | N11: 0 | P11: 0 | Q11: 2.5 | R11: Right | S11: 2.5 | W11: Goal Line
F12: =MOD(Table11[[#This Row],[Yard Line]],100)-MOD(E13,100) -> 0 | J12: Run | K12: R | L12: B | M12: 0 | N12: 0 | P12: 0 | Q12: 2.5 | R12: Right | S12: 2.5 | W12: Goal Line
F13: =MOD(Table11[[#This Row],[Yard Line]],100)-MOD(E14,100) -> 0 | J13: Run | K13: R | L13: C | M13: 0 | N13: 0 | P13: 0 | Q13: 2.5 | R13: Right | S13: 2.5 | W13: Goal Line
F14: =MOD(Table11[[#This Row],[Yard Line]],100)-MOD(E15,100) -> 0 | J14: Run | K14: L | L14: A | M14: 0 | N14: 0 | P14: 0 | Q14: 0.5 | R14: Left | S14: 2.5 | W14: Goal Line
F15: =MOD(Table11[[#This Row],[Yard Line]],100)-MOD(E16,100) -> 0 | J15: Run | K15: L | L15: B | M15: 0 | N15: 0 | P15: 0 | Q15: 0.5 | R15: Left | S15: 2.5 | W15: Goal Line
F16: =MOD(Table11[[#This Row],[Yard Line]],100)-MOD(E17,100) -> -65 | J16: Run | K16: L | L16: C | M16: 0 | N16: 0 | P16: 0 | Q16: 0.5 | R16: Left | S16: 2.5 | W16: Goal Line
A17: 3 | B17: 1 | C17: 1 | D17: 10 | E17: -35 | F17: -4 | G17: M | J17: Pass | K17: M | M17: 1 | N17: 0 | O17: S | P17: =Table11[[#This Row],[Gain/Loss]] -> -4 | Q17: =IF(Table11[[#This Row],[Direction]]="L",0.5,IF(Table11[[#This Row],[Direction]]="M",1.5,2.5)) -> 1.5 | R17: =IF(Table11[[#This Row],[Direction]]="R","Right",IF(Table11[[#This Row],[Direction]]="L","Left","Middle")) -> Middle | S17: =IF(Table11[[#This Row],[Pass Zone]]="S",0.5,IF(Table11[[#This Row],[Pass Zone]]="M",1.5,2.5)) -> 0.5 | T17: =IF(AND(Table11[[#This Row],[Direction]]="R",Table11[[#This Row],[Strength]]="R"),"Strong",IF(AND(Table11[[#This Row],[Direction]]="L",Table11[[#This Row],[Strength]]="L"),"Strong",IF(AND(Table11[[#This Row],[Direction]]="R",Table11[[#This Row],[Strength]]="L"),"Weak",IF(AND(Table11[[#This Row],[Direction]]="L",Table11[[#This Row],[Strength]]="R"),"Weak",IF(AND(Table11[[#This Row],[Strength]]="BAL",Table11[[#This Row],[Direction]]="M"),"BAL",""))))) | U17: =IF(AND(Table11[[#This Row],[Hash]]="R",Table11[[#This Row],[Direction]]="L"),"Field",IF(AND(Table11[[#This Row],[Hash]]="L",Table11[[#This Row],[Direction]]="R"),"Field",IF(AND(Table11[[#This Row],[Hash]]="R",Table11[[#This Row],[Direction]]="R"),"Boundry",IF(AND(Table11[[#This Row],[Hash]]="L",Table11[[#This Row],[Direction]]="L"),"Boundry","")))) | V17: =IF(AND(Table11[[#This Row],[Down]]=1,Table11[[#This Row],[Distance]]>9),"01: 1st & 10+",IF(AND(Table11[[#This Row],[Down]]=1,Table11[[#This Row],[Distance]]<10),"02: 1st & < 10",IF(AND(Table11[[#This Row],[Down]]=2,Table11[[#This Row],[Distance]]>7),"03: 2nd & 8+",IF(AND(Table11[[#This Row],[Down]]=2,Table11[[#This Row],[Distance]]>3,Table11[[#This Row],[Distance]]<8),"04: 2nd & 4 - 7",IF(AND(Table11[[#This Row],[Down]]=2,Table11[[#This Row],[Distance]]<4),"05: 2nd & < 4",IF(AND(Table11[[#This Row],[Down]]=3,Table11[[#This Row],[Distance]]>7),"06: 3rd & 8+",IF(AND(Table11[[#This Row],[Down]]=3,Table11[[#This Row],[Distance]]>3,Table11[[#This Row],[Distance]]<8),"07: 3rd & 4 - 7",IF(AND(Table11[[#This Row],[Down]]=3,Table11[[#This Row],[Distance]]<4),"08: 3rd & < 4",IF(AND(Table11[[#This Row],[Down]]=4,Table11[[#This Row],[Distance]]>1),"09: 4th & 2+",IF(AND(Table11[[#This Row],[Down]]=4,Table11[[#This Row],[Distance]]<2),"10: 4th & < 2"," ")))))))))) -> 01: 1st & 10+ | W17: =IF(AND(Table11[[#This Row],[Yard Line]]>-21,Table11[[#This Row],[Yard Line]]<-1),"0-20",IF(AND(Table11[[#This Row],[Yard Line]]>-50,Table11[[#This Row],[Yard Line]]<-20),"21-49",IF(AND(Table11[[#This Row],[Yard Line]]<51,Table11[[#This Row],[Yard Line]]>20),"50-21",IF(AND(Table11[[#This Row],[Yard Line]]<21,Table11[[#This Row],[Yard Line]]>2),"Red Zone",IF(Table11[[#This Row],[Yard Line]]<3,"Goal Line",""))))) -> 21-49
A18: 5 | B18: 2 | C18: 2 | D18: 9 | E18: -36 | F18: 0 | G18: M | J18: Pass | K18: M | M18: 1 | N18: 0 | O18: S | P18: =Table11[[#This Row],[Gain/Loss]] -> 0 | Q18: =IF(Table11[[#This Row],[Direction]]="L",0.5,IF(Table11[[#This Row],[Direction]]="M",1.5,2.5)) -> 1.5 | R18: =IF(Table11[[#This Row],[Direction]]="R","Right",IF(Table11[[#This Row],[Direction]]="L","Left","Middle")) -> Middle | S18: =IF(Table11[[#This Row],[Pass Zone]]="S",0.5,IF(Table11[[#This Row],[Pass Zone]]="M",1.5,2.5)) -> 0.5 | T18: =IF(AND(Table11[[#This Row],[Direction]]="R",Table11[[#This Row],[Strength]]="R"),"Strong",IF(AND(Table11[[#This Row],[Direction]]="L",Table11[[#This Row],[Strength]]="L"),"Strong",IF(AND(Table11[[#This Row],[Direction]]="R",Table11[[#This Row],[Strength]]="L"),"Weak",IF(AND(Table11[[#This Row],[Direction]]="L",Table11[[#This Row],[Strength]]="R"),"Weak",IF(AND(Table11[[#This Row],[Strength]]="BAL",Table11[[#This Row],[Direction]]="M"),"BAL",""))))) | U18: =IF(AND(Table11[[#This Row],[Hash]]="R",Table11[[#This Row],[Direction]]="L"),"Field",IF(AND(Table11[[#This Row],[Hash]]="L",Table11[[#This Row],[Direction]]="R"),"Field",IF(AND(Table11[[#This Row],[Hash]]="R",Table11[[#This Row],[Direction]]="R"),"Boundry",IF(AND(Table11[[#This Row],[Hash]]="L",Table11[[#This Row],[Direction]]="L"),"Boundry","")))) | V18: =IF(AND(Table11[[#This Row],[Down]]=1,Table11[[#This Row],[Distance]]>9),"01: 1st & 10+",IF(AND(Table11[[#This Row],[Down]]=1,Table11[[#This Row],[Distance]]<10),"02: 1st & < 10",IF(AND(Table11[[#This Row],[Down]]=2,Table11[[#This Row],[Distance]]>7),"03: 2nd & 8+",IF(AND(Table11[[#This Row],[Down]]=2,Table11[[#This Row],[Distance]]>3,Table11[[#This Row],[Distance]]<8),"04: 2nd & 4 - 7",IF(AND(Table11[[#This Row],[Down]]=2,Table11[[#This Row],[Distance]]<4),"05: 2nd & < 4",IF(AND(Table11[[#This Row],[Down]]=3,Table11[[#This Row],[Distance]]>7),"06: 3rd & 8+",IF(AND(Table11[[#This Row],[Down]]=3,Table11[[#This Row],[Distance]]>3,Table11[[#This Row],[Distance]]<8),"07: 3rd & 4 - 7",IF(AND(Table11[[#This Row],[Down]]=3,Table11[[#This Row],[Distance]]<4),"08: 3rd & < 4",IF(AND(Table11[[#This Row],[Down]]=4,Table11[[#This Row],[Distance]]>1),"09: 4th & 2+",IF(AND(Table11[[#This Row],[Down]]=4,Table11[[#This Row],[Distance]]<2),"10: 4th & < 2"," ")))))))))) -> 03: 2nd & 8+ | W18: =IF(AND(Table11[[#This Row],[Yard Line]]>-21,Table11[[#This Row],[Yard Line]]<-1),"0-20",IF(AND(Table11[[#This Row],[Yard Line]]>-50,Table11[[#This Row],[Yard Line]]<-20),"21-49",IF(AND(Table11[[#This Row],[Yard Line]]<51,Table11[[#This Row],[Yard Line]]>20),"50-21",IF(AND(Table11[[#This Row],[Yard Line]]<21,Table11[[#This Row],[Yard Line]]>2),"Red Zone",IF(Table11[[#This Row],[Yard Line]]<3,"Goal Line",""))))) -> 21-49
A19: 6 | B19: 3 | C19: 3 | D19: 9 | E19: -36 | F19: 13 | G19: M | J19: Run | K19: L | L19: C | M19: 1 | P19: =Table11[[#This Row],[Gain/Loss]] -> 13 | Q19: =IF(Table11[[#This Row],[Direction]]="L",0.5,IF(Table11[[#This Row],[Direction]]="M",1.5,2.5)) -> 0.5 | R19: =IF(Table11[[#This Row],[Direction]]="R","Right",IF(Table11[[#This Row],[Direction]]="L","Left","Middle")) -> Left | S19: =IF(Table11[[#This Row],[Pass Zone]]="S",0.5,IF(Table11[[#This Row],[Pass Zone]]="M",1.5,2.5)) -> 2.5 | T19: =IF(AND(Table11[[#This Row],[Direction]]="R",Table11[[#This Row],[Strength]]="R"),"Strong",IF(AND(Table11[[#This Row],[Direction]]="L",Table11[[#This Row],[Strength]]="L"),"Strong",IF(AND(Table11[[#This Row],[Direction]]="R",Table11[[#This Row],[Strength]]="L"),"Weak",IF(AND(Table11[[#This Row],[Direction]]="L",Table11[[#This Row],[Strength]]="R"),"Weak",IF(AND(Table11[[#This Row],[Strength]]="BAL",Table11[[#This Row],[Direction]]="M"),"BAL",""))))) | U19: =IF(AND(Table11[[#This Row],[Hash]]="R",Table11[[#This Row],[Direction]]="L"),"Field",IF(AND(Table11[[#This Row],[Hash]]="L",Table11[[#This Row],[Direction]]="R"),"Field",IF(AND(Table11[[#This Row],[Hash]]="R",Table11[[#This Row],[Direction]]="R"),"Boundry",IF(AND(Table11[[#This Row],[Hash]]="L",Table11[[#This Row],[Direction]]="L"),"Boundry","")))) | V19: =IF(AND(Table11[[#This Row],[Down]]=1,Table11[[#This Row],[Distance]]>9),"01: 1st & 10+",IF(AND(Table11[[#This Row],[Down]]=1,Table11[[#This Row],[Distance]]<10),"02: 1st & < 10",IF(AND(Table11[[#This Row],[Down]]=2,Table11[[#This Row],[Distance]]>7),"03: 2nd & 8+",IF(AND(Table11[[#This Row],[Down]]=2,Table11[[#This Row],[Distance]]>3,Table11[[#This Row],[Distance]]<8),"04: 2nd & 4 - 7",IF(AND(Table11[[#This Row],[Down]]=2,Table11[[#This Row],[Distance]]<4),"05: 2nd & < 4",IF(AND(Table11[[#This Row],[Down]]=3,Table11[[#This Row],[Distance]]>7),"06: 3rd & 8+",IF(AND(Table11[[#This Row],[Down]]=3,Table11[[#This Row],[Distance]]>3,Table11[[#This Row],[Distance]]<8),"07: 3rd & 4 - 7",IF(AND(Table11[[#This Row],[Down]]=3,Table11[[#This Row],[Distance]]<4),"08: 3rd & < 4",IF(AND(Table11[[#This Row],[Down]]=4,Table11[[#This Row],[Distance]]>1),"09: 4th & 2+",IF(AND(Table11[[#This Row],[Down]]=4,Table11[[#This Row],[Distance]]<2),"10: 4th & < 2"," ")))))))))) -> 06: 3rd & 8+ | W19: =IF(AND(Table11[[#This Row],[Yard Line]]>-21,Table11[[#This Row],[Yard Line]]<-1),"0-20",IF(AND(Table11[[#This Row],[Yard Line]]>-50,Table11[[#This Row],[Yard Line]]<-20),"21-49",IF(AND(Table11[[#This Row],[Yard Line]]<51,Table11[[#This Row],[Yard Line]]>20),"50-21",IF(AND(Table11[[#This Row],[Yard Line]]<21,Table11[[#This Row],[Yard Line]]>2),"Red Zone",IF(Table11[[#This Row],[Yard Line]]<3,"Goal Line",""))))) -> 21-49
A20: 8 | B20: 2 | C20: 2 | D20: 23 | E20: -36 | F20: 1 | G20: R | J20: Run | K20: L | L20: B | M20: 1 | P20: =Table11[[#This Row],[Gain/Loss]] -> 1 | Q20: =IF(Table11[[#This Row],[Direction]]="L",0.5,IF(Table11[[#This Row],[Direction]]="M",1.5,2.5)) -> 0.5 | R20: =IF(Table11[[#This Row],[Direction]]="R","Right",IF(Table11[[#This Row],[Direction]]="L","Left","Middle")) -> Left | S20: =IF(Table11[[#This Row],[Pass Zone]]="S",0.5,IF(Table11[[#This Row],[Pass Zone]]="M",1.5,2.5)) -> 2.5 | T20: =IF(AND(Table11[[#This Row],[Direction]]="R",Table11[[#This Row],[Strength]]="R"),"Strong",IF(AND(Table11[[#This Row],[Direction]]="L",Table11[[#This Row],[Strength]]="L"),"Strong",IF(AND(Table11[[#This Row],[Direction]]="R",Table11[[#This Row],[Strength]]="L"),"Weak",IF(AND(Table11[[#This Row],[Direction]]="L",Table11[[#This Row],[Strength]]="R"),"Weak",IF(AND(Table11[[#This Row],[Strength]]="BAL",Table11[[#This Row],[Direction]]="M"),"BAL",""))))) | U20: =IF(AND(Table11[[#This Row],[Hash]]="R",Table11[[#This Row],[Direction]]="L"),"Field",IF(AND(Table11[[#This Row],[Hash]]="L",Table11[[#This Row],[Direction]]="R"),"Field",IF(AND(Table11[[#This Row],[Hash]]="R",Table11[[#This Row],[Direction]]="R"),"Boundry",IF(AND(Table11[[#This Row],[Hash]]="L",Table11[[#This Row],[Direction]]="L"),"Boundry","")))) -> Field | V20: =IF(AND(Table11[[#This Row],[Down]]=1,Table11[[#This Row],[Distance]]>9),"01: 1st & 10+",IF(AND(Table11[[#This Row],[Down]]=1,Table11[[#This Row],[Distance]]<10),"02: 1st & < 10",IF(AND(Table11[[#This Row],[Down]]=2,Table11[[#This Row],[Distance]]>7),"03: 2nd & 8+",IF(AND(Table11[[#This Row],[Down]]=2,Table11[[#This Row],[Distance]]>3,Table11[[#This Row],[Distance]]<8),"04: 2nd & 4 - 7",IF(AND(Table11[[#This Row],[Down]]=2,Table11[[#This Row],[Distance]]<4),"05: 2nd & < 4",IF(AND(Table11[[#This Row],[Down]]=3,Table11[[#This Row],[Distance]]>7),"06: 3rd & 8+",IF(AND(Table11[[#This Row],[Down]]=3,Table11[[#This Row],[Distance]]>3,Table11[[#This Row],[Distance]]<8),"07: 3rd & 4 - 7",IF(AND(Table11[[#This Row],[Down]]=3,Table11[[#This Row],[Distance]]<4),"08: 3rd & < 4",IF(AND(Table11[[#This Row],[Down]]=4,Table11[[#This Row],[Distance]]>1),"09: 4th & 2+",IF(AND(Table11[[#This Row],[Down]]=4,Table11[[#This Row],[Distance]]<2),"10: 4th & < 2"," ")))))))))) -> 03: 2nd & 8+ | W20: =IF(AND(Table11[[#This Row],[Yard Line]]>-21,Table11[[#This Row],[Yard Line]]<-1),"0-20",IF(AND(Table11[[#This Row],[Yard Line]]>-50,Table11[[#This Row],[Yard Line]]<-20),"21-49",IF(AND(Table11[[#This Row],[Yard Line]]<51,Table11[[#This Row],[Yard Line]]>20),"50-21",IF(AND(Table11[[#This Row],[Yard Line]]<21,Table11[[#This Row],[Yard Line]]>2),"Red Zone",IF(Table11[[#This Row],[Yard Line]]<3,"Goal Line",""))))) -> 21-49
A21: 9 | B21: 3 | C21: 3 | D21: 22 | E21: -37 | F21: 0 | G21: L | J21: Run | K21: R | L21: B | M21: 1 | P21: =Table11[[#This Row],[Gain/Loss]] -> 0 | Q21: =IF(Table11[[#This Row],[Direction]]="L",0.5,IF(Table11[[#This Row],[Direction]]="M",1.5,2.5)) -> 2.5 | R21: =IF(Table11[[#This Row],[Direction]]="R","Right",IF(Table11[[#This Row],[Direction]]="L","Left","Middle")) -> Right | S21: =IF(Table11[[#This Row],[Pass Zone]]="S",0.5,IF(Table11[[#This Row],[Pass Zone]]="M",1.5,2.5)) -> 2.5 | T21: =IF(AND(Table11[[#This Row],[Direction]]="R",Table11[[#This Row],[Strength]]="R"),"Strong",IF(AND(Table11[[#This Row],[Direction]]="L",Table11[[#This Row],[Strength]]="L"),"Strong",IF(AND(Table11[[#This Row],[Direction]]="R",Table11[[#This Row],[Strength]]="L"),"Weak",IF(AND(Table11[[#This Row],[Direction]]="L",Table11[[#This Row],[Strength]]="R"),"Weak",IF(AND(Table11[[#This Row],[Strength]]="BAL",Table11[[#This Row],[Direction]]="M"),"BAL",""))))) | U21: =IF(AND(Table11[[#This Row],[Hash]]="R",Table11[[#This Row],[Direction]]="L"),"Field",IF(AND(Table11[[#This Row],[Hash]]="L",Table11[[#This Row],[Direction]]="R"),"Field",IF(AND(Table11[[#This Row],[Hash]]="R",Table11[[#This Row],[Direction]]="R"),"Boundry",IF(AND(Table11[[#This Row],[Hash]]="L",Table11[[#This Row],[Direction]]="L"),"Boundry","")))) -> Field | V21: =IF(AND(Table11[[#This Row],[Down]]=1,Table11[[#This Row],[Distance]]>9),"01: 1st & 10+",IF(AND(Table11[[#This Row],[Down]]=1,Table11[[#This Row],[Distance]]<10),"02: 1st & < 10",IF(AND(Table11[[#This Row],[Down]]=2,Table11[[#This Row],[Distance]]>7),"03: 2nd & 8+",IF(AND(Table11[[#This Row],[Down]]=2,Table11[[#This Row],[Distance]]>3,Table11[[#This Row],[Distance]]<8),"04: 2nd & 4 - 7",IF(AND(Table11[[#This Row],[Down]]=2,Table11[[#This Row],[Distance]]<4),"05: 2nd & < 4",IF(AND(Table11[[#This Row],[Down]]=3,Table11[[#This Row],[Distance]]>7),"06: 3rd & 8+",IF(AND(Table11[[#This Row],[Down]]=3,Table11[[#This Row],[Distance]]>3,Table11[[#This Row],[Distance]]<8),"07: 3rd & 4 - 7",IF(AND(Table11[[#This Row],[Down]]=3,Table11[[#This Row],[Distance]]<4),"08: 3rd & < 4",IF(AND(Table11[[#This Row],[Down]]=4,Table11[[#This Row],[Distance]]>1),"09: 4th & 2+",IF(AND(Table11[[#This Row],[Down]]=4,Table11[[#This Row],[Distance]]<2),"10: 4th & < 2"," ")))))))))) -> 06: 3rd & 8+ | W21: =IF(AND(Table11[[#This Row],[Yard Line]]>-21,Table11[[#This Row],[Yard Line]]<-1),"0-20",IF(AND(Table11[[#This Row],[Yard Line]]>-50,Table11[[#This Row],[Yard Line]]<-20),"21-49",IF(AND(Table11[[#This Row],[Yard Line]]<51,Table11[[#This Row],[Yard Line]]>20),"50-21",IF(AND(Table11[[#This Row],[Yard Line]]<21,Table11[[#This Row],[Yard Line]]>2),"Red Zone",IF(Table11[[#This Row],[Yard Line]]<3,"Goal Line",""))))) -> 21-49
A22: 18 | B22: 1 | C22: 1 | D22: 10 | E22: 36 | F22: 5 | G22: R | J22: Run | K22: R | L22: B | M22: 1 | P22: =Table11[[#This Row],[Gain/Loss]] -> 5 | Q22: =IF(Table11[[#This Row],[Direction]]="L",0.5,IF(Table11[[#This Row],[Direction]]="M",1.5,2.5)) -> 2.5 | R22: =IF(Table11[[#This Row],[Direction]]="R","Right",IF(Table11[[#This Row],[Direction]]="L","Left","Middle")) -> Right | S22: =IF(Table11[[#This Row],[Pass Zone]]="S",0.5,IF(Table11[[#This Row],[Pass Zone]]="M",1.5,2.5)) -> 2.5 | T22: =IF(AND(Table11[[#This Row],[Direction]]="R",Table11[[#This Row],[Strength]]="R"),"Strong",IF(AND(Table11[[#This Row],[Direction]]="L",Table11[[#This Row],[Strength]]="L"),"Strong",IF(AND(Table11[[#This Row],[Direction]]="R",Table11[[#This Row],[Strength]]="L"),"Weak",IF(AND(Table11[[#This Row],[Direction]]="L",Table11[[#This Row],[Strength]]="R"),"Weak",IF(AND(Table11[[#This Row],[Strength]]="BAL",Table11[[#This Row],[Direction]]="M"),"BAL",""))))) | U22: =IF(AND(Table11[[#This Row],[Hash]]="R",Table11[[#This Row],[Direction]]="L"),"Field",IF(AND(Table11[[#This Row],[Hash]]="L",Table11[[#This Row],[Direction]]="R"),"Field",IF(AND(Table11[[#This Row],[Hash]]="R",Table11[[#This Row],[Direction]]="R"),"Boundry",IF(AND(Table11[[#This Row],[Hash]]="L",Table11[[#This Row],[Direction]]="L"),"Boundry","")))) -> Boundry | V22: =IF(AND(Table11[[#This Row],[Down]]=1,Table11[[#This Row],[Distance]]>9),"01: 1st & 10+",IF(AND(Table11[[#This Row],[Down]]=1,Table11[[#This Row],[Distance]]<10),"02: 1st & < 10",IF(AND(Table11[[#This Row],[Down]]=2,Table11[[#This Row],[Distance]]>7),"03: 2nd & 8+",IF(AND(Table11[[#This Row],[Down]]=2,Table11[[#This Row],[Distance]]>3,Table11[[#This Row],[Distance]]<8),"04: 2nd & 4 - 7",IF(AND(Table11[[#This Row],[Down]]=2,Table11[[#This Row],[Distance]]<4),"05: 2nd & < 4",IF(AND(Table11[[#This Row],[Down]]=3,Table11[[#This Row],[Distance]]>7),"06: 3rd & 8+",IF(AND(Table11[[#This Row],[Down]]=3,Table11[[#This Row],[Distance]]>3,Table11[[#This Row],[Distance]]<8),"07: 3rd & 4 - 7",IF(AND(Table11[[#This Row],[Down]]=3,Table11[[#This Row],[Distance]]<4),"08: 3rd & < 4",IF(AND(Table11[[#This Row],[Down]]=4,Table11[[#This Row],[Distance]]>1),"09: 4th & 2+",IF(AND(Table11[[#This Row],[Down]]=4,Table11[[#This Row],[Distance]]<2),"10: 4th & < 2"," ")))))))))) -> 01: 1st & 10+ | W22: =IF(AND(Table11[[#This Row],[Yard Line]]>-21,Table11[[#This Row],[Yard Line]]<-1),"0-20",IF(AND(Table11[[#This Row],[Yard Line]]>-50,Table11[[#This Row],[Yard Line]]<-20),"21-49",IF(AND(Table11[[#This Row],[Yard Line]]<51,Table11[[#This Row],[Yard Line]]>20),"50-21",IF(AND(Table11[[#This Row],[Yard Line]]<21,Table11[[#This Row],[Yard Line]]>2),"Red Zone",IF(Table11[[#This Row],[Yard Line]]<3,"Goal Line",""))))) -> 50-21
A23: 19 | B23: 2 | C23: 2 | D23: 5 | E23: 31 | F23: 2 | G23: R | J23: Run | K23: L | L23: B | M23: 1 | P23: =Table11[[#This Row],[Gain/Loss]] -> 2 | Q23: =IF(Table11[[#This Row],[Direction]]="L",0.5,IF(Table11[[#This Row],[Direction]]="M",1.5,2.5)) -> 0.5 | R23: =IF(Table11[[#This Row],[Direction]]="R","Right",IF(Table11[[#This Row],[Direction]]="L","Left","Middle")) -> Left | S23: =IF(Table11[[#This Row],[Pass Zone]]="S",0.5,IF(Table11[[#This Row],[Pass Zone]]="M",1.5,2.5)) -> 2.5 | T23: =IF(AND(Table11[[#This Row],[Direction]]="R",Table11[[#This Row],[Strength]]="R"),"Strong",IF(AND(Table11[[#This Row],[Direction]]="L",Table11[[#This Row],[Strength]]="L"),"Strong",IF(AND(Table11[[#This Row],[Direction]]="R",Table11[[#This Row],[Strength]]="L"),"Weak",IF(AND(Table11[[#This Row],[Direction]]="L",Table11[[#This Row],[Strength]]="R"),"Weak",IF(AND(Table11[[#This Row],[Strength]]="BAL",Table11[[#This Row],[Direction]]="M"),"BAL",""))))) | U23: =IF(AND(Table11[[#This Row],[Hash]]="R",Table11[[#This Row],[Direction]]="L"),"Field",IF(AND(Table11[[#This Row],[Hash]]="L",Table11[[#This Row],[Direction]]="R"),"Field",IF(AND(Table11[[#This Row],[Hash]]="R",Table11[[#This Row],[Direction]]="R"),"Boundry",IF(AND(Table11[[#This Row],[Hash]]="L",Table11[[#This Row],[Direction]]="L"),"Boundry","")))) -> Field | V23: =IF(AND(Table11[[#This Row],[Down]]=1,Table11[[#This Row],[Distance]]>9),"01: 1st & 10+",IF(AND(Table11[[#This Row],[Down]]=1,Table11[[#This Row],[Distance]]<10),"02: 1st & < 10",IF(AND(Table11[[#This Row],[Down]]=2,Table11[[#This Row],[Distance]]>7),"03: 2nd & 8+",IF(AND(Table11[[#This Row],[Down]]=2,Table11[[#This Row],[Distance]]>3,Table11[[#This Row],[Distance]]<8),"04: 2nd & 4 - 7",IF(AND(Table11[[#This Row],[Down]]=2,Table11[[#This Row],[Distance]]<4),"05: 2nd & < 4",IF(AND(Table11[[#This Row],[Down]]=3,Table11[[#This Row],[Distance]]>7),"06: 3rd & 8+",IF(AND(Table11[[#This Row],[Down]]=3,Table11[[#This Row],[Distance]]>3,Table11[[#This Row],[Distance]]<8),"07: 3rd & 4 - 7",IF(AND(Table11[[#This Row],[Down]]=3,Table11[[#This Row],[Distance]]<4),"08: 3rd & < 4",IF(AND(Table11[[#This Row],[Down]]=4,Table11[[#This Row],[Distance]]>1),"09: 4th & 2+",IF(AND(Table11[[#This Row],[Down]]=4,Table11[[#This Row],[Distance]]<2),"10: 4th & < 2"," ")))))))))) -> 04: 2nd & 4 - 7 | W23: =IF(AND(Table11[[#This Row],[Yard Line]]>-21,Table11[[#This Row],[Yard Line]]<-1),"0-20",IF(AND(Table11[[#This Row],[Yard Line]]>-50,Table11[[#This Row],[Yard Line]]<-20),"21-49",IF(AND(Table11[[#This Row],[Yard Line]]<51,Table11[[#This Row],[Yard Line]]>20),"50-21",IF(AND(Table11[[#This Row],[Yard Line]]<21,Table11[[#This Row],[Yard Line]]>2),"Red Zone",IF(Table11[[#This Row],[Yard Line]]<3,"Goal Line",""))))) -> 50-21
A24: 20 | B24: 3 | C24: 3 | D24: 3 | E24: 29 | F24: 0 | G24: M | J24: Run | K24: R | L24: B | M24: 1 | P24: =Table11[[#This Row],[Gain/Loss]] -> 0 | Q24: =IF(Table11[[#This Row],[Direction]]="L",0.5,IF(Table11[[#This Row],[Direction]]="M",1.5,2.5)) -> 2.5 | R24: =IF(Table11[[#This Row],[Direction]]="R","Right",IF(Table11[[#This Row],[Direction]]="L","Left","Middle")) -> Right | S24: =IF(Table11[[#This Row],[Pass Zone]]="S",0.5,IF(Table11[[#This Row],[Pass Zone]]="M",1.5,2.5)) -> 2.5 | T24: =IF(AND(Table11[[#This Row],[Direction]]="R",Table11[[#This Row],[Strength]]="R"),"Strong",IF(AND(Table11[[#This Row],[Direction]]="L",Table11[[#This Row],[Strength]]="L"),"Strong",IF(AND(Table11[[#This Row],[Direction]]="R",Table11[[#This Row],[Strength]]="L"),"Weak",IF(AND(Table11[[#This Row],[Direction]]="L",Table11[[#This Row],[Strength]]="R"),"Weak",IF(AND(Table11[[#This Row],[Strength]]="BAL",Table11[[#This Row],[Direction]]="M"),"BAL",""))))) | U24: =IF(AND(Table11[[#This Row],[Hash]]="R",Table11[[#This Row],[Direction]]="L"),"Field",IF(AND(Table11[[#This Row],[Hash]]="L",Table11[[#This Row],[Direction]]="R"),"Field",IF(AND(Table11[[#This Row],[Hash]]="R",Table11[[#This Row],[Direction]]="R"),"Boundry",IF(AND(Table11[[#This Row],[Hash]]="L",Table11[[#This Row],[Direction]]="L"),"Boundry","")))) | V24: =IF(AND(Table11[[#This Row],[Down]]=1,Table11[[#This Row],[Distance]]>9),"01: 1st & 10+",IF(AND(Table11[[#This Row],[Down]]=1,Table11[[#This Row],[Distance]]<10),"02: 1st & < 10",IF(AND(Table11[[#This Row],[Down]]=2,Table11[[#This Row],[Distance]]>7),"03: 2nd & 8+",IF(AND(Table11[[#This Row],[Down]]=2,Table11[[#This Row],[Distance]]>3,Table11[[#This Row],[Distance]]<8),"04: 2nd & 4 - 7",IF(AND(Table11[[#This Row],[Down]]=2,Table11[[#This Row],[Distance]]<4),"05: 2nd & < 4",IF(AND(Table11[[#This Row],[Down]]=3,Table11[[#This Row],[Distance]]>7),"06: 3rd & 8+",IF(AND(Table11[[#This Row],[Down]]=3,Table11[[#This Row],[Distance]]>3,Table11[[#This Row],[Distance]]<8),"07: 3rd & 4 - 7",IF(AND(Table11[[#This Row],[Down]]=3,Table11[[#This Row],[Distance]]<4),"08: 3rd & < 4",IF(AND(Table11[[#This Row],[Down]]=4,Table11[[#This Row],[Distance]]>1),"09: 4th & 2+",IF(AND(Table11[[#This Row],[Down]]=4,Table11[[#This Row],[Distance]]<2),"10: 4th & < 2"," ")))))))))) -> 08: 3rd & < 4 | W24: =IF(AND(Table11[[#This Row],[Yard Line]]>-21,Table11[[#This Row],[Yard Line]]<-1),"0-20",IF(AND(Table11[[#This Row],[Yard Line]]>-50,Table11[[#This Row],[Yard Line]]<-20),"21-49",IF(AND(Table11[[#This Row],[Yard Line]]<51,Table11[[#This Row],[Yard Line]]>20),"50-21",IF(AND(Table11[[#This Row],[Yard Line]]<21,Table11[[#This Row],[Yard Line]]>2),"Red Zone",IF(Table11[[#This Row],[Yard Line]]<3,"Goal Line",""))))) -> 50-21
